<?xml version="1.0" ?>
<sdf version="1.6">
  <model name="line_follower_bot">
    <static>false</static>

    <!-- Base -->
    <link name="chassis">
      <pose>0 0 0.05 0 0 0</pose>
      <inertial>
        <mass>1.0</mass>
        <inertia>
          <ixx>0.01</ixx>
          <iyy>0.01</iyy>
          <izz>0.02</izz>
        </inertia>
      </inertial>
      <visual name="body">
        <geometry>
          <box><size>0.2 0.15 0.05</size></box>
        </geometry>
        <material>
          <ambient>0.3 0.3 0.3 1</ambient>
          <diffuse>0.5 0.5 0.5 1</diffuse>
        </material>
      </visual>
    </link>

    <!-- Left wheel -->
    <link name="left_wheel">
      <pose>0 0.08 0.025 0 0 0</pose>
      <visual name="left_wheel_visual">
        <geometry>
          <cylinder>
            <radius>0.03</radius>
            <length>0.02</length>
          </cylinder>
        </geometry>
        <material><diffuse>0 0 0 1</diffuse></material>
      </visual>
      <collision name="left_wheel_collision">
        <geometry>
          <cylinder>
            <radius>0.03</radius>
            <length>0.02</length>
          </cylinder>
        </geometry>
      </collision>
    </link>

    <!-- Right wheel -->
    <link name="right_wheel">
      <pose>0 -0.08 0.025 0 0 0</pose>
      <visual name="right_wheel_visual">
        <geometry>
          <cylinder>
            <radius>0.03</radius>
            <length>0.02</length>
          </cylinder>
        </geometry>
        <material><diffuse>0 0 0 1</diffuse></material>
      </visual>
      <collision name="right_wheel_collision">
        <geometry>
          <cylinder>
            <radius>0.03</radius>
            <length>0.02</length>
          </cylinder>
        </geometry>
      </collision>
    </link>

    <!-- Joints -->
    <joint name="left_wheel_joint" type="revolute">
      <parent>chassis</parent>
      <child>left_wheel</child>
      <pose>0 0 0 0 0 0</pose>
      <axis>
        <xyz>0 1 0</xyz>
        <limit>
          <lower>-1000</lower>
          <upper>1000</upper>
        </limit>
      </axis>
    </joint>

    <joint name="right_wheel_joint" type="revolute">
      <parent>chassis</parent>
      <child>right_wheel</child>
      <pose>0 0 0 0 0 0</pose>
      <axis>
        <xyz>0 1 0</xyz>
        <limit>
          <lower>-1000</lower>
          <upper>1000</upper>
        </limit>
      </axis>
    </joint>

    <!-- Camera sensor -->
    <link name="camera_link">
      <pose>0 0 0.15 0 0 0</pose>
      <sensor name="camera" type="camera">
        <update_rate>30</update_rate>
        <camera>
          <horizontal_fov>1.396</horizontal_fov>
          <image>
            <width>320</width>
            <height>240</height>
            <format>R8G8B8</format>
          </image>
          <clip><near>0.01</near><far>10</far></clip>
        </camera>
        <always_on>true</always_on>
        <visualize>true</visualize>
        <plugin name="camera_controller" filename="libgazebo_ros_camera.so">
          <ros>
            <namespace>/</namespace>
            <remapping>image_raw:=/camera/image_raw</remapping>
          </ros>
          <frame_name>camera_link</frame_name>
        </plugin>
      </sensor>
    </link>

    <!-- Differential Drive Plugin -->
    <plugin name="diff_drive" filename="libgazebo_ros_diff_drive.so">
      <ros>
        <namespace>/</namespace>
        <remapping>cmd_vel:=/cmd_vel</remapping>
        <remapping>odom:=/odom</remapping>
      </ros>
      <update_rate>50.0</update_rate>
      <left_joint>left_wheel_joint</left_joint>
      <right_joint>right_wheel_joint</right_joint>
      <wheel_separation>0.16</wheel_separation>
      <wheel_radius>0.03</wheel_radius>
      <publish_odom>true</publish_odom>
      <publish_tf>true</publish_tf>
    </plugin>
  </model>
</sdf>
